<mujoco model="flamingo_p_v0">
    <compiler angle="radian" eulerseq="XYZ" inertiafromgeom="false" balanceinertia="true"/>
    <option timestep="0.005" gravity="0 0 -9.807" iterations="50" solver="Newton" jacobian="dense" integrator="implicitfast"/>

    <visual>
        <headlight diffuse="1 1 1" ambient="0.3 0.3 0.3" specular="0 0 0"/>
        <rgba haze="0.15 0.25 0.35 1"/>
        <global azimuth="220" elevation="-20"/>
    </visual>

    <default>
        <default class="visual">
            <geom type="mesh" contype="0" conaffinity="0" group="2"/>
        </default>

        <default class="collision">
            <geom group="3"/>
        </default>

        <default class="collision_mesh">
            <geom contype="1" conaffinity="1" group="0"/>
        </default>

        <joint damping="1.0" stiffness="0.0" frictionloss="0.1" armature="0.01" actuatorfrclimited="true" actuatorfrcrange="-1000 1000"/>
        <default class="wheels">
            <joint damping="0.0" stiffness="0.0" frictionloss="0.1" armature="0.01" actuatorfrclimited="true" actuatorfrcrange="-1000 1000"/>
        </default>
    </default>

    <worldbody>
        <geom name="ground" pos="0 0 0" type="hfield" material="MatPlane" friction="0.8 0.02 0.01" condim="3"/>
        <body name="base_link" pos="0.00000000 0.00000000 0.61282" quat="1 0 0 0">
            <inertial pos="-0.02184 0.00062 -0.10961"
                      mass="4.80547"
                      fullinertia="0.02944743384 0.05419484353 0.06358515462 -0.00042110648 0.00070940118 0.00020477916"/>
            <geom type="mesh" mesh="base_link"
                  rgba="0.752941176470588 0.752941176470588 0.752941176470588 1"
                  class="visual"/>
            <site name="base_link_site" pos="0 0 0" size="0.01" rgba="0.2 0.2 0.2 1" />
            <joint name="base_free_joint" type="free" damping="0.0" />
            <site name="imu" size="0.01" pos="0.0 0 0.0"/>

            <body name="left_hip_link"
                  pos="0.11825 0.0765 -0.086692"
                  quat="0.4999981633974483 0.49999999999662686 -0.5000018366025516 -0.49999999999662686">
                <inertial pos="0.02714 0.00001 0.06679"
                          mass="1.24046"
                          fullinertia="0.00247653769 0.00211394268 0.00132533038 -0.00000569149 0.00012317420 -0.00000048610"/>
                <joint name="left_hip_joint" range="-0.6 0.6" axis="0 0 1" actuatorfrcrange="-60 60" />
                <geom type="mesh" rgba="0.752941176470588 0.752941176470588 0.752941176470588 1" mesh="left_hip_link" class="visual"/>

                <body name="left_shoulder_link"
                      pos="0.0066 0 0.0735"
                      quat="0.7071054825112363 0.0 -0.7071080798594735 0.0">
                    <inertial pos="0.04003 -0.02840 0.06599"
                              mass="2.12968"
                              fullinertia="0.00842704930 0.01155772717 0.01621457911 -0.00633517377 0.00195856088 -0.00138731586"/>
                    <joint name="left_shoulder_joint" range="-1.6 1.53" axis="0 0 1" actuatorfrcrange="-60 60" />
                    <geom type="mesh" rgba="0.752941176470588 0.752941176470588 0.752941176470588 1" mesh="left_shoulder_link" class="visual"/>

                    <body name="left_leg_link" pos="0.19142 -0.20435 0.089" quat="1.0 0.0 0.0 0.0">
                        <inertial pos="-0.14325 -0.17443 -0.00932"
                                  mass="0.93631"
                                  fullinertia="0.00679397067 0.00448112204 0.01082623424 0.00486203521 0.00030907162 0.00039752931"/>
                        <joint name="left_leg_joint" range="-0.64 1.35" axis="0 0 1" actuatorfrcrange="-60 60" />
                        <geom type="mesh" rgba="0.203921568627451 0.203921568627451 0.203921568627451 1" mesh="left_leg_link"/>

                        <body name="left_wheel_link" pos="-0.17756 -0.21931 0.0035" quat="1.0 0.0 0.0 0.0">
                            <inertial pos="0.0 0.0 0.03736"
                                      mass="0.58347"
                                      fullinertia="0.00155907903 0.00155907902 0.00296447680 -0.00000000001 -0.00000000031 -0.00000000049"/>
                            <joint name="left_wheel_joint" range="0 0" axis="0 0 1" actuatorfrcrange="-36 36" class="wheels"/>
                            <geom type="mesh" rgba="0.792156862745098 0.819607843137255 0.933333333333333 1" mesh="left_wheel_link"/>
                        </body>
                    </body>
                </body>
            </body>

            <body name="right_hip_link"
                  pos="0.11825 -0.0765 -0.086692"
                  quat="0.4999981633974483 0.49999999999662686 -0.5000018366025516 -0.49999999999662686">
                <inertial pos="-0.02714 -0.00001 0.06679"
                          mass="1.24046"
                          fullinertia="0.00247653769 0.00211394268 0.00132533038 -0.00000569149 -0.00012317420 0.00000048610"/>
                <joint name="right_hip_joint" range="-0.6 0.6" axis="0 0 1" actuatorfrcrange="-60 60" />
                <geom type="mesh" rgba="0.752941176470588 0.752941176470588 0.752941176470588 1" mesh="right_hip_link" class="visual"/>

                <body name="right_shoulder_link"
                      pos="-0.0066 0 0.0735"
                      quat="0.7071054825112363 0.0 0.7071080798594735 0.0">
                    <inertial pos="-0.03997 -0.02849 0.06592"
                              mass="2.12280"
                              fullinertia="0.00841707608 0.01155066545 0.01620612000 0.00634563897 -0.00195537833 -0.00139798556"/>
                    <joint name="right_shoulder_joint" range="-1.6 1.53" axis="0 0 -1" actuatorfrcrange="-60 60" />
                    <geom type="mesh" rgba="0.796078431372549 0.823529411764706 0.937254901960784 1" mesh="right_shoulder_link" class="visual"/>

                    <body name="right_leg_link" pos="-0.19142 -0.20435 0.089" quat="1.0 0.0 0.0 0.0">
                        <inertial pos="0.14319 -0.17435 -0.00932"
                                  mass="0.93668"
                                  fullinertia="0.00680716942 0.00448827456 0.01084659345 -0.00487174083 -0.00030904729 0.00039748699"/>
                        <joint name="right_leg_joint" range="-0.64 1.35" axis="0 0 -1" actuatorfrcrange="-60 60" />
                        <geom type="mesh" rgba="0.203921568627451 0.203921568627451 0.203921568627451 1" mesh="right_leg_link"/>

                        <body name="right_wheel_link" pos="0.17756 -0.21931 0.0035" quat="1.0 0.0 0.0 0.0">
                            <inertial pos="0.0 0.0 0.03736"
                                      mass="0.58347"
                                      fullinertia="0.00155907903 0.00155907903 0.00296447680 0.00000000001 -0.00000000056 0.00000000012"/>
                            <joint name="right_wheel_joint" range="0 0" axis="0 0 -1" actuatorfrcrange="-36 36" class="wheels"/>
                            <geom type="mesh" rgba="0.298039215686275 0.298039215686275 0.298039215686275 1" mesh="right_wheel_link"/>
                        </body>
                    </body>
                </body>
            </body>
        </body>
    </worldbody>

    <asset>
        <texture type="skybox" builtin="gradient" rgb1="0.3 0.5 0.7" rgb2="0 0 0" width="512" height="3072"/>
        <texture type="2d" name="groundplane" builtin="checker" mark="edge" rgb1="0.2 0.3 0.4" rgb2="0.1 0.2 0.3" markrgb="0.8 0.8 0.8" width="300" height="300"/>
        <material name="MatPlane" texture="groundplane" texuniform="true" texrepeat="5 5" reflectance="0.2"/>
        <material name="rubber" rgba="0.4 0.4 0.4 1" shininess="0.5" reflectance="0.2"/>

        <mesh name="base_link" file="../mesh/base_link.STL" />
        <mesh name="left_hip_link" file="../mesh/left_hip_link.STL" />
        <mesh name="left_shoulder_link" file="../mesh/left_shoulder_link.STL" />
        <mesh name="left_leg_link" file="../mesh/left_leg_link.STL" />
        <mesh name="left_wheel_link" file="../mesh/left_wheel_link.STL" />
        <mesh name="right_hip_link" file="../mesh/right_hip_link.STL" />
        <mesh name="right_shoulder_link" file="../mesh/right_shoulder_link.STL" />
        <mesh name="right_leg_link" file="../mesh/right_leg_link.STL" />
        <mesh name="right_wheel_link" file="../mesh/right_wheel_link.STL" />

        <hfield name="flat" file="../terrain/flat.png" nrow="256" ncol="256" size="140 140 10 0.1"/>
        <hfield name="rocky_easy" file="../terrain/rocky_easy.png" nrow="512" ncol="512" size="140 140 0.1 0.1"/>
        <hfield name="rocky_hard" file="../terrain/rocky_hard.png" nrow="512" ncol="512" size="140 140 0.25 0.1"/>
        <hfield name="slope_easy" file="../terrain/slope_easy.png" nrow="512" ncol="512" size="140 140 0.5 0.1"/>
        <hfield name="slope_hard" file="../terrain/slope_hard.png" nrow="512" ncol="512" size="140 140 1 0.1"/>
        <hfield name="stairs_up_light" file="../terrain/stairs_up_light.png" nrow="1024" ncol="1024" size="5 5 0.55 0.5"/>
        <hfield name="stairs_up_easy" file="../terrain/stairs_up_easy.png" nrow="512" ncol="512" size="5 5 0.60 0.5"/>
        <hfield name="stairs_up_normal" file="../terrain/stairs_up_normal.png" nrow="512" ncol="512" size="5 5 0.7 0.5"/>
        <hfield name="stairs_up_hard" file="../terrain/stairs_up_hard.png" nrow="512" ncol="512" size="5 5 0.825 0.5"/>
    </asset>

    <actuator>
        <motor joint="left_hip_joint" name="left_hip_joint" ctrllimited="true" ctrlrange="-1000 1000" gear="1" />
        <motor joint="right_hip_joint" name="right_hip_joint" ctrllimited="true" ctrlrange="-1000 1000" gear="1"/>
        <motor joint="left_shoulder_joint" name="left_shoulder_joint" ctrllimited="true" ctrlrange="-1000 1000" gear="1"/>
        <motor joint="right_shoulder_joint" name="right_shoulder_joint" ctrllimited="true" ctrlrange="-1000 1000" gear="1"/>
        <motor joint="left_leg_joint" name="left_leg_joint" ctrllimited="true" ctrlrange="-1000 1000" gear="1"/>
        <motor joint="right_leg_joint" name="right_leg_joint" ctrllimited="true" ctrlrange="-1000 1000" gear="1"/>
        <motor joint="left_wheel_joint" name="left_wheel_joint" ctrllimited="true" ctrlrange="-1000 1000" gear="1"/>
        <motor joint="right_wheel_joint" name="right_wheel_joint" ctrllimited="true" ctrlrange="-1000 1000" gear="1"/>
    </actuator>

    <sensor>
        <framequat name="orientation" objtype="site" noise="0.1" objname="imu"/>
        <framepos name="position" objtype="site" noise="0.1" objname="imu"/>
        <gyro name="angular-velocity" site="imu" noise="0.2" cutoff="34.9"/>
        <velocimeter name="linear-velocity" site="imu" noise="0.1" cutoff="30"/>
        <accelerometer name="linear-acceleration" site="imu" noise="0.05" cutoff="157"/>
        <magnetometer name="magnetometer" site="imu"/>
    </sensor>
</mujoco>
